Workbook

Sheet Calculs ingredients (en gr)
A1: Feuille de calcul des mélanges de remblai en pâte cimenté (RPC) + granulat conscassé (RPCg) au laboratoire en fixant
A2: le pourcentage solide massique initial du mélange (Cw%)
A3: ã Tikou Belem (2016) | G3: Granulat considéré comme substitut aux résidus (en proportion massique ou volumique)
B4: # Projet | F4: note: | G4: texte noir, case mauve: à remplir par l'opérateur
B5: Opérateur | G5: Texte rouge, case brune: peut être modifié par l'opérateur au besoin
B6: Date | G6: Toutes les autres cases ne doivemt pas être modifiées (formules de calculs)
B7: Laboratoire
G8: Pour un mélange à slump constant, il est conseillé de partir d'un %solide de 80% (ou autre)
B9: Résidus | C9: Westwood | D9: Granulats | G9: puis d'ajuster les mélanges en jouant avec l'ajout des ingrédients (selon les résidus et/ou granulats)
B10: Gs résidus | C10: =(2.7+3.3)/2 -> 3 | D10: Gs granulat | E10: 2.7
B11: teneur en eau | C11: 0 | F11: Calcul pour teneur en eau massique
B12: Cw% résidus | C12: =(1/(1+C11))*1 -> 1 | E12: tare
E13: tare + mh
E14: tare + ms | G14: *obtenue généralement à 50°C après 48h ou à 105°C après 24h
D16: Recette 1
B17: # Batch LABO
B18: diam. moule (pouce) | D18: 2
B19: hauteur du moule (pouce) | D19: =2*D18 -> 4
B20: nb. moules | D20: 10
B21: % solide initial visé Cw% remblai | D21: 0.73
B22: Proportion massique de liant (%) | D22: 0.05
A23: %massique | B23: %m granulat p/r résidus secs (%) | D23: 0
A24: %volumique | B24: %vol. granulat p/r résidus secs (%) | D24: =(D42/$E$10)/(D42/$E$10+D41/$C$10) -> 0
A25: %volumique | B25: %vol. granulat p/r remblai (%) | D25: =(D42/$E$10)/(D38) -> 0
B26: Eau/Liant initial ou W/C initial | D26: =(D44)/(D43) -> 7.7671233
B27: Facteur de sécurité (%) | D27: 0.25
B28: (T10) GU | C28: 3.15 | D28: 0.2
B29: (T50) HS | C29: 3.18
B30: (T30) HE | C30: 3.15
B31: Slag (GGBFS) | C31: 2.9 | D31: 0.8
B32: FA (types C, F) | C32: 2.3
B33: Chaux | C33: 2.6
B34: Gs résidus + granulat (gr/cc) | D34: =(D23/$E$10+(1-$D$23)/$C$10)^-1 -> 3
B35: Gs-liant composé (gr/cc) | D35: =(D28/$C$28+D29/$C$29+D30/$C$30+D31/$C$31+D32/$C$32+D33/$C$33)^-1 -> 2.9467742
B36: Gs pâte (résidus+granulat+liant) | D36: =(1+D22)/((1/$D$34)+(D22/D35)) -> 2.9974219
B37: Volume contenant (cm³) | D37: =PI()/4*(D18*2.54)^2*(D19*2.54) -> 205.92592
B38: Volume total pâte VT (cm³) | D38: =D37*D20*(1+D27) -> 2574.074
B39: Masse solide calc. Md (gr) | D39: =(D21*D38)*((D21/D36)+(1-D21)/1)^-1 -> 3659.0419
A40: Sr (%) | B40: Degré de saturation initial (%) | D40: =(D36*(1/D21-1))/((D38*D36)/D39-1) -> 1
B41: Masse sèche résidus Ms-t (gr) | D41: =(1-D23)*(D39/(1+D22)) -> 3484.8019
...

Sheet Synthese calculs
B2: ='Calculs ingredients (en gr)'!B4 -> # Projet | D2: ='Calculs ingredients (en gr)'!C4 -> 0
B3: ='Calculs ingredients (en gr)'!B5 -> Opérateur | D3: ='Calculs ingredients (en gr)'!C5 -> 0
B4: ='Calculs ingredients (en gr)'!B6 -> Date
B5: ='Calculs ingredients (en gr)'!B9 -> Résidus | D5: ='Calculs ingredients (en gr)'!C9 -> Westwood | F5: ='Calculs ingredients (en gr)'!D9 -> Granulats | G5: ='Calculs ingredients (en gr)'!E9 -> 0
B6: ='Calculs ingredients (en gr)'!B7 -> Laboratoire | D6: ='Calculs ingredients (en gr)'!C7 -> 0
B8: ='Calculs ingredients (en gr)'!B47:C47 -> #Batch | D8: ='Calculs ingredients (en gr)'!D47:E47 -> Recette 1
B9: ='Calculs ingredients (en gr)'!B48:C48 -> Masse de granulat sec (gr) | D9: ='Calculs ingredients (en gr)'!D48:E48 -> 0
B10: ='Calculs ingredients (en gr)'!B49:C49 -> Masse résidus humides (gr) | D10: ='Calculs ingredients (en gr)'!D49:E49 -> 3484.8019
B11: ='Calculs ingredients (en gr)'!B50:C50 -> masse eau à ajouter (gr) | D11: ='Calculs ingredients (en gr)'!D50:E50 -> 1353.3443
B12: ='Calculs ingredients (en gr)'!B51:C51 -> Masse liants (gr) | C12: ='Calculs ingredients (en gr)'!C51:D51 -> (T10) GU | D12: ='Calculs ingredients (en gr)'!D51:E51 -> 34.848019
C13: ='Calculs ingredients (en gr)'!C52:D52 -> (T50) HS | D13: ='Calculs ingredients (en gr)'!D52:E52 -> 0
C14: ='Calculs ingredients (en gr)'!C53:D53 -> (T30) HE | D14: ='Calculs ingredients (en gr)'!D53:E53 -> 0
C15: ='Calculs ingredients (en gr)'!C54:D54 -> Slag (GGBFS) | D15: ='Calculs ingredients (en gr)'!D54:E54 -> 139.39207
C16: ='Calculs ingredients (en gr)'!C55:D55 -> FA (types C, F) | D16: ='Calculs ingredients (en gr)'!D55:E55 -> 0
C17: ='Calculs ingredients (en gr)'!C56:D56 -> Chaux | D17: ='Calculs ingredients (en gr)'!D56:E56 -> 0
B18: ='Calculs ingredients (en gr)'!B57:C57 -> Masse/volume eau ajoutée (gr) | D18: ='Calculs ingredients (en gr)'!D57:E57 -> 0
B19: ='Calculs ingredients (en gr)'!B58:C58 -> Masse de granulat ajouté (gr) | D19: ='Calculs ingredients (en gr)'!D58:E58 -> 0
B20: ='Calculs ingredients (en gr)'!B60:C60 -> M résidus secs ajoutés corresp. (gr) | D20: ='Calculs ingredients (en gr)'!D60:E60 -> 0
B21: ='Calculs ingredients (en gr)'!B59:C59 -> M résidus humides ajoutés (gr) | D21: ='Calculs ingredients (en gr)'!D59:E59 -> 0
A22: ajustement | B22: ='Calculs ingredients (en gr)'!B65:C65 -> Masse liant à ajouter - ajuster (gr) | D22: ='Calculs ingredients (en gr)'!D65:E65 -> 0
B23: ='Calculs ingredients (en gr)'!B66:C66 -> Masse liants (gr) | C23: ='Calculs ingredients (en gr)'!C66:D66 -> (T10) GU | D23: ='Calculs ingredients (en gr)'!D66:E66 -> 0
C24: ='Calculs ingredients (en gr)'!C67:D67 -> (T50) HS | D24: ='Calculs ingredients (en gr)'!D67:E67 -> 0
C25: ='Calculs ingredients (en gr)'!C68:D68 -> (T30) HE | D25: ='Calculs ingredients (en gr)'!D68:E68 -> 0
C26: ='Calculs ingredients (en gr)'!C69:D69 -> Slag (GGBFS) | D26: ='Calculs ingredients (en gr)'!D69:E69 -> 0
C27: ='Calculs ingredients (en gr)'!C70:D70 -> FA (types C, F) | D27: ='Calculs ingredients (en gr)'!D70:E70 -> 0
C28: ='Calculs ingredients (en gr)'!C71:D71 -> Chaux | D28: ='Calculs ingredients (en gr)'!D71:E71 -> 0
B30: ='Calculs ingredients (en gr)'!B72:C72 -> slump mesuré (mm)
B31: ='Calculs ingredients (en gr)'!B73:C73 -> tare (gr)
B32: ='Calculs ingredients (en gr)'!B74:C74 -> m_humide pâte (gr)
B33: ='Calculs ingredients (en gr)'!B75:C75 -> m_sèche pâte (gr)
B34: ='Calculs ingredients (en gr)'!B76:C76 -> teneur eau mesurée w(%)
B35: ='Calculs ingredients (en gr)'!B77:C77 -> % solide massique mesuré Cw(%)
