Workbook

Sheet calculs cremblai-granulats
B1: Feuille de calcul des mélanges de remblai en pâte + granulat conscassé au laboratoire en fixant
B2: le pourcentage solide massique initial du mélange (Cw%)
G3: Granulat considéré comme substitut aux résidus
B4: # Projet | F4: note: | G4: texte noir, cases mauves à remplir par l'opérateur
B5: Opérateur | G5: Texte rouge, case brune: peut être modifié par l'opérateur au besoin
B6: Date | G6: Toutes les autres cases ne doivemt pas être modifiées (formules de calculs)
B7: #URSTM
G8: Pour un mélange à slump constant, ils est conseillé de partir d'1 %solide de 80% | M8: densité stérile LaRonde
B9: Résidus | C9: résidus Casa Berardi | D9: Granulat | E9: concassé LaRonde | G9: Pour les mélanges suivants, ajuster en fonction des résultats obtenus. | M9: 2.887422
B10: GS résidus | C10: 3.05 | D10: Gs granulat | E10: 2.8 | M10: 2.729148
B11: teneur en eau | C11: =H11 -> 0.31578947 | F11: Calcul | H11: =1/0.76-1 -> 0.31578947 | M11: 2.733471
B12: % solide | C12: =(1/(1+C11))*1 -> 0.76 | E12: tare | F12: 2278.8 | H12: =100/4 -> 25 | K12: 2278.8 | M12: =AVERAGE(M9:M11) -> 2.783347
E13: tare + mh | F13: 2947.3 | K13: 2947.3
E14: tare + ms | F14: 2831.8 | G14: *obtenue généralement à 50°C après 48h ou à 105°C après 24h | K14: 2831.8
D16: Mélange 1
B17: # Batch URSTM | F17: =C10/(C10+(D41/D42)*(E10/C10)) -> #DIV/0!
B18: diam. moule (pouce) | D18: 394 | F18: =(D41/C10)+(D42/E10) -> 4559.5087 | G18: =(D41+D42)/D34 -> 4559.5087
B19: H. moule (pouce) | D19: 310 | E19: 2 | F19: =E19*D23 -> 0
B20: nb. moules | D20: 17.76019
B21: % solide initial avec granulat | D21: =G54 -> 0.7
B22: proportion de liant (%) | D22: 0.045
B23: %m granulat p/r résidus secs (%) | D23: 0
B24: %vol. granulat p/r résidus secs (%) | D24: =(D42/$E$10)/(D42/$E$10+D41/$C$10) -> 0
B25: %vol. granulat p/r remblai (%) | D25: =(D42/$E$10)/(D38) -> 0
B26: Eau/Liant initial ou W/C initial | D26: =(D44)/(D43) -> 9.952381
B27: facteur de sécurité (%) | D27: 0
B28: (T10) GU | C28: 3.15 | D28: 0.2
B29: (T50) HS | C29: 3.18 | E29: e | F29: rau-h
B30: (T30) HE | C30: 3.15 | E30: =D36/F32-1 -> 1.305174 | F30: =(D21/D36+(1-D21)/1)^-1 -> 1.8873109
B31: Slag (GGBFS) | C31: 2.9 | D31: 0.8 | E31: Sr | F31: rau-d
B32: FA (types C, F) | C32: 2.3 | E32: =(D36*(1/D21-1))/E30 -> 1 | F32: =F30/(1/D21-1+1) -> 1.3211176
B33: Chaux | C33: 2.6
B34: Gs résidus + granulat (t/cc) | D34: =(D23/$E$10+(1-D23)/$C$10)^-1 -> 3.05
B35: Gs-liant composé (t/cc) | D35: =(D28/$C$28+D29/$C$29+D30/$C$30+D31/$C$31+D32/$C$32+D33/$C$33)^-1 -> 2.9467742 | E35: =D28*C28+D31*C31 -> 2.95
B36: Gs pâte (résidus+granulat+liant) | D36: =(1+D22)/(((1-D23)/(C10)+D23/(E10))+(D22/D35)) -> 3.0454061
B37: Volume contenant (m³) | D37: =55*20*10 -> 11000
B38: Volume total pâte VT (m³) | D38: =D37*1*(1+D27) -> 11000
A39: (rau_w = 1) | B39: Masse solide calc. Md (t) | D39: =(D21*D38)*((D21/D36)+(1-D21)/1)^-1 -> 14532.294
B40: degré de saturation initial(%) | D40: =(D36*(1/D21-1))/((D38*D36)/D39-1) -> 1
B41: Masse sèche résidus Ms-t (t) | D41: =(1-D23)*(D39/(1+D22)) -> 13906.501 | E41: =(1/0.75-1)*D41 -> 4635.5005
...

Sheet feuille préparation mélanges
B2: ='calculs cremblai-granulats'!B4 -> # Projet | D2: ='calculs cremblai-granulats'!C4 -> 0
B3: ='calculs cremblai-granulats'!B5 -> Opérateur | D3: ='calculs cremblai-granulats'!C5 -> 0
B4: ='calculs cremblai-granulats'!B6 -> Date
B5: ='calculs cremblai-granulats'!B9 -> Résidus | D5: ='calculs cremblai-granulats'!C9 -> résidus Casa Berardi | F5: ='calculs cremblai-granulats'!D9 -> Granulat | G5: ='calculs cremblai-granulats'!E9 -> concassé LaRonde
B6: ='calculs cremblai-granulats'!B7 -> #URSTM | D6: ='calculs cremblai-granulats'!C7 -> 0
B8: ='calculs cremblai-granulats'!B47:C47 -> #Batch | D8: ='calculs cremblai-granulats'!D47:E47 -> Mélange 1
B9: ='calculs cremblai-granulats'!B48:C48 -> Masse de granulat sec (t) | D9: ='calculs cremblai-granulats'!D48:E48 -> 0
B10: ='calculs cremblai-granulats'!B49:C49 -> Masse résidus humides (t) | D10: ='calculs cremblai-granulats'!D49:E49 -> 18298.028
B11: ='calculs cremblai-granulats'!B50:C50 -> masse eau à ajouter (t) | D11: ='calculs cremblai-granulats'!D50:E50 -> 1836.5992
B12: ='calculs cremblai-granulats'!B51:C51 -> Masse liants (t) | C12: ='calculs cremblai-granulats'!C51:D51 -> (T10) GU | D12: ='calculs cremblai-granulats'!D51:E51 -> 125.15851
C13: ='calculs cremblai-granulats'!C52:D52 -> (T50) HS | D13: ='calculs cremblai-granulats'!D52:E52 -> 0
C14: ='calculs cremblai-granulats'!C53:D53 -> (T30) HE | D14: ='calculs cremblai-granulats'!D53:E53 -> 0
C15: ='calculs cremblai-granulats'!C54:D54 -> Slag (GGBFS) | D15: ='calculs cremblai-granulats'!D54:E54 -> 500.63405
C16: ='calculs cremblai-granulats'!C55:D55 -> FA (types C, F) | D16: ='calculs cremblai-granulats'!D55:E55 -> 0
C17: ='calculs cremblai-granulats'!C56:D56 -> Chaux | D17: ='calculs cremblai-granulats'!D56:E56 -> 0
B18: ='calculs cremblai-granulats'!B57:C57 -> Masse/volume eau ajoutée (t) | D18: ='calculs cremblai-granulats'!D57:E57 -> 0.5
B19: ='calculs cremblai-granulats'!B58:C58 -> Masse de granulat ajouté (t) | D19: ='calculs cremblai-granulats'!D58:E58 -> 0
B20: ='calculs cremblai-granulats'!B60:C60 -> M résidus secs ajoutés corresp. (t) | D20: ='calculs cremblai-granulats'!D60:E60 -> 0
B21: ='calculs cremblai-granulats'!B59:C59 -> M résidus humides ajoutés (t) | D21: ='calculs cremblai-granulats'!D59:E59 -> 0
A22: ajustement | B22: ='calculs cremblai-granulats'!B65:C65 -> Masse liant à ajouter - ajuster (g) | D22: ='calculs cremblai-granulats'!D65:E65 -> 0
B23: ='calculs cremblai-granulats'!B66:C66 -> Masse liants (t) | C23: ='calculs cremblai-granulats'!C66:D66 -> (T10) GU | D23: ='calculs cremblai-granulats'!D66:E66 -> 0
C24: ='calculs cremblai-granulats'!C67:D67 -> (T50) HS | D24: ='calculs cremblai-granulats'!D67:E67 -> 0
C25: ='calculs cremblai-granulats'!C68:D68 -> (T30) HE | D25: ='calculs cremblai-granulats'!D68:E68 -> 0
C26: ='calculs cremblai-granulats'!C69:D69 -> Slag (GGBFS) | D26: ='calculs cremblai-granulats'!D69:E69 -> 0
C27: ='calculs cremblai-granulats'!C70:D70 -> FA (types C, F) | D27: ='calculs cremblai-granulats'!D70:E70 -> 0
C28: ='calculs cremblai-granulats'!C71:D71 -> Chaux | D28: ='calculs cremblai-granulats'!D71:E71 -> 0
B30: ='calculs cremblai-granulats'!B72:C72 -> slump mesuré (mm)
B31: ='calculs cremblai-granulats'!B73:C73 -> tare (g)
B32: ='calculs cremblai-granulats'!B74:C74 -> m_h pâte (g)
B33: ='calculs cremblai-granulats'!B75:C75 -> m_s pâte (g)
B34: ='calculs cremblai-granulats'!B76:C76 -> teneur eau mesurée w(%)
B35: ='calculs cremblai-granulats'!B77:C77 -> % solide massique mesuré Cw(%)
